Workbook

Sheet Cadastro Indicadores
A2: Dados dos indicadores materno-infantis
A3: Dados transcritos do documento disponibilizado. As linhas vazias ao final podem ser usadas para os próximos períodos.
A5: periodo_referencia | B5: codigo_indicador | C5: nome_indicador | D5: tipo_atendimento | E5: detalhamento | F5: resultado_informado | G5: numerador | H5: denominador | I5: resultado_para_dashboard | J5: unidade_medida | K5: justificativa_observacao | L5: relatorio_fonte | M5: data_do_registro | N5: area_responsavel | O5: situacao_do_dado | P5: conferencia_preenchimento
A6: 46023 | B6: 2017 | C6: =IFERROR(VLOOKUP(B6,Referência!$A$5:$I$16,2,FALSE),"") -> Percentual de recém-nascidos com amamentação na primeira hora de vida | D6: SUS | E6: Sem detalhamento | F6: 0.932 | G6: 82 | H6: 88 | I6: =IF(B6="","",IF(F6<>"",F6,IF(AND(G6<>"",H6<>""),IF(H6=0,"",G6/H6),""))) -> 0.932 | J6: =IFERROR(VLOOKUP(B6,Referência!$A$5:$I$16,9,FALSE),"") -> percentual | K6: RN prematuro; indisposição materna; desconforto respiratório agudo. | L6: Relatório cód. 2017 | M6: 46276 | N6: Coordenação da Maternidade | O6: Transcrito do documento | P6: =IF(B6="","",IF(OR(A6="",C6="",D6="",E6="",I6="",J6="",L6="",M6="",N6="",O6=""),"INCOMPLETO","COMPLETO")) -> COMPLETO
A7: 46023 | B7: 2017 | C7: =IFERROR(VLOOKUP(B7,Referência!$A$5:$I$16,2,FALSE),"") -> Percentual de recém-nascidos com amamentação na primeira hora de vida | D7: Saúde suplementar | E7: Sem detalhamento | F7: 0.875 | G7: 56 | H7: 64 | I7: =IF(B7="","",IF(F7<>"",F7,IF(AND(G7<>"",H7<>""),IF(H7=0,"",G7/H7),""))) -> 0.875 | J7: =IFERROR(VLOOKUP(B7,Referência!$A$5:$I$16,9,FALSE),"") -> percentual | K7: Indisposição materna; RN nauseado; intercorrência materna. | L7: Relatório cód. 2017 | M7: 46276 | N7: Coordenação da Maternidade | O7: Transcrito do documento | P7: =IF(B7="","",IF(OR(A7="",C7="",D7="",E7="",I7="",J7="",L7="",M7="",N7="",O7=""),"INCOMPLETO","COMPLETO")) -> COMPLETO
A8: 46054 | B8: 2017 | C8: =IFERROR(VLOOKUP(B8,Referência!$A$5:$I$16,2,FALSE),"") -> Percentual de recém-nascidos com amamentação na primeira hora de vida | D8: SUS | E8: Sem detalhamento | F8: 0.923 | G8: 60 | H8: 65 | I8: =IF(B8="","",IF(F8<>"",F8,IF(AND(G8<>"",H8<>""),IF(H8=0,"",G8/H8),""))) -> 0.923 | J8: =IFERROR(VLOOKUP(B8,Referência!$A$5:$I$16,9,FALSE),"") -> percentual | K8: RN PIG; sofrimento fetal agudo; desconforto respiratório agudo. | L8: Relatório cód. 2017 | M8: 46276 | N8: Coordenação da Maternidade | O8: Transcrito do documento | P8: =IF(B8="","",IF(OR(A8="",C8="",D8="",E8="",I8="",J8="",L8="",M8="",N8="",O8=""),"INCOMPLETO","COMPLETO")) -> COMPLETO
A9: 46054 | B9: 2017 | C9: =IFERROR(VLOOKUP(B9,Referência!$A$5:$I$16,2,FALSE),"") -> Percentual de recém-nascidos com amamentação na primeira hora de vida | D9: Saúde suplementar | E9: Sem detalhamento | F9: 0.868 | G9: 59 | H9: 68 | I9: =IF(B9="","",IF(F9<>"",F9,IF(AND(G9<>"",H9<>""),IF(H9=0,"",G9/H9),""))) -> 0.868 | J9: =IFERROR(VLOOKUP(B9,Referência!$A$5:$I$16,9,FALSE),"") -> percentual | K9: RN em observação; necessidade de CPAP; prematuridade; mãe após anestesia geral. | L9: Relatório cód. 2017 | M9: 46276 | N9: Coordenação da Maternidade | O9: Transcrito do documento | P9: =IF(B9="","",IF(OR(A9="",C9="",D9="",E9="",I9="",J9="",L9="",M9="",N9="",O9=""),"INCOMPLETO","COMPLETO")) -> COMPLETO
A10: 46082 | B10: 2017 | C10: =IFERROR(VLOOKUP(B10,Referência!$A$5:$I$16,2,FALSE),"") -> Percentual de recém-nascidos com amamentação na primeira hora de vida | D10: SUS | E10: Sem detalhamento | F10: 0.945 | G10: 121 | H10: 128 | I10: =IF(B10="","",IF(F10<>"",F10,IF(AND(G10<>"",H10<>""),IF(H10=0,"",G10/H10),""))) -> 0.945 | J10: =IFERROR(VLOOKUP(B10,Referência!$A$5:$I$16,9,FALSE),"") -> percentual | K10: Prematuridade; desconforto respiratório agudo. | L10: Relatório cód. 2017 | M10: 46276 | N10: Coordenação da Maternidade | O10: Transcrito do documento | P10: =IF(B10="","",IF(OR(A10="",C10="",D10="",E10="",I10="",J10="",L10="",M10="",N10="",O10=""),"INCOMPLETO","COMPLETO")) -> COMPLETO
A11: 46082 | B11: 2017 | C11: =IFERROR(VLOOKUP(B11,Referência!$A$5:$I$16,2,FALSE),"") -> Percentual de recém-nascidos com amamentação na primeira hora de vida | D11: Saúde suplementar | E11: Sem detalhamento | F11: 0.85 | G11: 68 | H11: 80 | I11: =IF(B11="","",IF(F11<>"",F11,IF(AND(G11<>"",H11<>""),IF(H11=0,"",G11/H11),""))) -> 0.85 | J11: =IFERROR(VLOOKUP(B11,Referência!$A$5:$I$16,9,FALSE),"") -> percentual | K11: Aquecimento e observação; prematuridade; necessidade de CPAP. | L11: Relatório cód. 2017 | M11: 46276 | N11: Coordenação da Maternidade | O11: Transcrito do documento | P11: =IF(B11="","",IF(OR(A11="",C11="",D11="",E11="",I11="",J11="",L11="",M11="",N11="",O11=""),"INCOMPLETO","COMPLETO")) -> COMPLETO
A12: 46113 | B12: 2017 | C12: =IFERROR(VLOOKUP(B12,Referência!$A$5:$I$16,2,FALSE),"") -> Percentual de recém-nascidos com amamentação na primeira hora de vida | D12: SUS | E12: Sem detalhamento | F12: 0.906 | G12: 87 | H12: 96 | I12: =IF(B12="","",IF(F12<>"",F12,IF(AND(G12<>"",H12<>""),IF(H12=0,"",G12/H12),""))) -> 0.906 | J12: =IFERROR(VLOOKUP(B12,Referência!$A$5:$I$16,9,FALSE),"") -> percentual | K12: Prematuridade; RN nasceu em apneia. | L12: Relatório cód. 2017 | M12: 46276 | N12: Coordenação da Maternidade | O12: Transcrito do documento | P12: =IF(B12="","",IF(OR(A12="",C12="",D12="",E12="",I12="",J12="",L12="",M12="",N12="",O12=""),"INCOMPLETO","COMPLETO")) -> COMPLETO
A13: 46113 | B13: 2017 | C13: =IFERROR(VLOOKUP(B13,Referência!$A$5:$I$16,2,FALSE),"") -> Percentual de recém-nascidos com amamentação na primeira hora de vida | D13: Saúde suplementar | E13: Sem detalhamento | F13: 0.814 | G13: 48 | H13: 59 | I13: =IF(B13="","",IF(F13<>"",F13,IF(AND(G13<>"",H13<>""),IF(H13=0,"",G13/H13),""))) -> 0.814 | J13: =IFERROR(VLOOKUP(B13,Referência!$A$5:$I$16,9,FALSE),"") -> percentual | K13: Aquecimento e observação; desconforto respiratório agudo; prematuridade. | L13: Relatório cód. 2017 | M13: 46276 | N13: Coordenação da Maternidade | O13: Transcrito do documento | P13: =IF(B13="","",IF(OR(A13="",C13="",D13="",E13="",I13="",J13="",L13="",M13="",N13="",O13=""),"INCOMPLETO","COMPLETO")) -> COMPLETO
A14: 46143 | B14: 2017 | C14: =IFERROR(VLOOKUP(B14,Referência!$A$5:$I$16,2,FALSE),"") -> Percentual de recém-nascidos com amamentação na primeira hora de vida | D14: SUS | E14: Sem detalhamento | F14: 0.947 | G14: 89 | H14: 94 | I14: =IF(B14="","",IF(F14<>"",F14,IF(AND(G14<>"",H14<>""),IF(H14=0,"",G14/H14),""))) -> 0.947 | J14: =IFERROR(VLOOKUP(B14,Referência!$A$5:$I$16,9,FALSE),"") -> percentual | K14: Prematuridade; desconforto respiratório agudo; escolha materna. | L14: Relatório cód. 2017 | M14: 46276 | N14: Coordenação da Maternidade | O14: Transcrito do documento | P14: =IF(B14="","",IF(OR(A14="",C14="",D14="",E14="",I14="",J14="",L14="",M14="",N14="",O14=""),"INCOMPLETO","COMPLETO")) -> COMPLETO
A15: 46143 | B15: 2017 | C15: =IFERROR(VLOOKUP(B15,Referência!$A$5:$I$16,2,FALSE),"") -> Percentual de recém-nascidos com amamentação na primeira hora de vida | D15: Saúde suplementar | E15: Sem detalhamento | F15: 0.857 | G15: 60 | H15: 70 | I15: =IF(B15="","",IF(F15<>"",F15,IF(AND(G15<>"",H15<>""),IF(H15=0,"",G15/H15),""))) -> 0.857 | J15: =IFERROR(VLOOKUP(B15,Referência!$A$5:$I$16,9,FALSE),"") -> percentual | K15: Retenção placentária; desconforto respiratório agudo; HIV positivo; mãe após anestesia geral; prematuridade. | L15: Relatório cód. 2017 | M15: 46276 | N15: Coordenação da Maternidade | O15: Transcrito do documento | P15: =IF(B15="","",IF(OR(A15="",C15="",D15="",E15="",I15="",J15="",L15="",M15="",N15="",O15=""),"INCOMPLETO","COMPLETO")) -> COMPLETO
A16: 46174 | B16: 2017 | C16: =IFERROR(VLOOKUP(B16,Referência!$A$5:$I$16,2,FALSE),"") -> Percentual de recém-nascidos com amamentação na primeira hora de vida | D16: SUS | E16: Sem detalhamento | F16: 0.865 | G16: 90 | H16: 104 | I16: =IF(B16="","",IF(F16<>"",F16,IF(AND(G16<>"",H16<>""),IF(H16=0,"",G16/H16),""))) -> 0.865 | J16: =IFERROR(VLOOKUP(B16,Referência!$A$5:$I$16,9,FALSE),"") -> percentual | K16: Desconforto respiratório agudo; mãe sem sorologias e aguardando exames; hemorragia pós-parto; taquipneia transitória; CPAP. | L16: Relatório cód. 2017 | M16: 46276 | N16: Coordenação da Maternidade | O16: Transcrito do documento | P16: =IF(B16="","",IF(OR(A16="",C16="",D16="",E16="",I16="",J16="",L16="",M16="",N16="",O16=""),"INCOMPLETO","COMPLETO")) -> COMPLETO
A17: 46174 | B17: 2017 | C17: =IFERROR(VLOOKUP(B17,Referência!$A$5:$I$16,2,FALSE),"") -> Percentual de recém-nascidos com amamentação na primeira hora de vida | D17: Saúde suplementar | E17: Sem detalhamento | F17: 0.935 | G17: 58 | H17: 62 | I17: =IF(B17="","",IF(F17<>"",F17,IF(AND(G17<>"",H17<>""),IF(H17=0,"",G17/H17),""))) -> 0.935 | J17: =IFERROR(VLOOKUP(B17,Referência!$A$5:$I$16,9,FALSE),"") -> percentual | K17: Taquipneia transitória; hemorragia pós-parto; observação e aquecimento na UCI. | L17: Relatório cód. 2017 | M17: 46276 | N17: Coordenação da Maternidade | O17: Transcrito do documento | P17: =IF(B17="","",IF(OR(A17="",C17="",D17="",E17="",I17="",J17="",L17="",M17="",N17="",O17=""),"INCOMPLETO","COMPLETO")) -> COMPLETO
... A33: 46235 | B33: 2097 | C33: =IFERROR(VLOOKUP(B33,Referência!$A$5:$I$16,2,FALSE),"") -> Tempo médio de internação do RN de risco | D33: Saúde suplementar | E33: Sem detalhamento | F33: 7.3 | G33: 65.7 | H33: 9 | I33: =IF(B33="","",IF(F33<>"",F33,IF(AND(G33<>"",H33<>""),IF(H33=0,"",G33/H33),""))) -> 7.3 | J33: =IFERROR(VLOOKUP(B33,Referência!$A$5:$I$16,9,FALSE),"") -> dias | K33: 55 RN avaliados; 9 RN de risco (16,36%). | L33: Relatório cód. 2097 | M33: 46276 | N33: Coordenação da Maternidade | O33: Transcrito do documento | P33: =IF(B33="","",IF(OR(A33="",C33="",D33="",E33="",I33="",J33="",L33="",M33="",N33="",O33=""),"INCOMPLETO","COMPLETO")) -> COMPLETO
A34: 46082 | B34: CRITERIOS_RN_RISCO | C34: =IFERROR(VLOOKUP(B34,Referência!$A$5:$I$16,2,FALSE),"") -> Critérios identificados nos RN classificados como de risco | D34: SUS | E34: Má formação congênita | F34: 0 | I34: =IF(B34="","",IF(F34<>"",F34,IF(AND(G34<>"",H34<>""),IF(H34=0,"",G34/H34),""))) -> 0 | J34: =IFERROR(VLOOKUP(B34,Referência!$A$5:$I$16,9,FALSE),"") -> quantidade | K34: Um mesmo RN pode apresentar mais de um critério. | L34: Relatório analítico de critérios de risco dos RN | M34: 46276 | N34: Coordenação da Maternidade | O34: Transcrito do documento | P34: =IF(B34="","",IF(OR(A34="",C34="",D34="",E34="",I34="",J34="",L34="",M34="",N34="",O34=""),"INCOMPLETO","COMPLETO")) -> COMPLETO
A35: 46082 | B35: CRITERIOS_RN_RISCO | C35: =IFERROR(VLOOKUP(B35,Referência!$A$5:$I$16,2,FALSE),"") -> Critérios identificados nos RN classificados como de risco | D35: SUS | E35: Prematuridade abaixo de 37 semanas de idade gestacional | F35: 8 | I35: =IF(B35="","",IF(F35<>"",F35,IF(AND(G35<>"",H35<>""),IF(H35=0,"",G35/H35),""))) -> 8 | J35: =IFERROR(VLOOKUP(B35,Referência!$A$5:$I$16,9,FALSE),"") -> quantidade | K35: Um mesmo RN pode apresentar mais de um critério. | L35: Relatório analítico de critérios de risco dos RN | M35: 46276 | N35: Coordenação da Maternidade | O35: Transcrito do documento | P35: =IF(B35="","",IF(OR(A35="",C35="",D35="",E35="",I35="",J35="",L35="",M35="",N35="",O35=""),"INCOMPLETO","COMPLETO")) -> COMPLETO
A36: 46082 | B36: CRITERIOS_RN_RISCO | C36: =IFERROR(VLOOKUP(B36,Referência!$A$5:$I$16,2,FALSE),"") -> Critérios identificados nos RN classificados como de risco | D36: SUS | E36: Icterícia em nível de exsanguineotransfusão | F36: 1 | I36: =IF(B36="","",IF(F36<>"",F36,IF(AND(G36<>"",H36<>""),IF(H36=0,"",G36/H36),""))) -> 1 | J36: =IFERROR(VLOOKUP(B36,Referência!$A$5:$I$16,9,FALSE),"") -> quantidade | K36: Um mesmo RN pode apresentar mais de um critério. | L36: Relatório analítico de critérios de risco dos RN | M36: 46276 | N36: Coordenação da Maternidade | O36: Transcrito do documento | P36: =IF(B36="","",IF(OR(A36="",C36="",D36="",E36="",I36="",J36="",L36="",M36="",N36="",O36=""),"INCOMPLETO","COMPLETO")) -> COMPLETO
A37: 46082 | B37: CRITERIOS_RN_RISCO | C37: =IFERROR(VLOOKUP(B37,Referência!$A$5:$I$16,2,FALSE),"") -> Critérios identificados nos RN classificados como de risco | D37: SUS | E37: Sepse ou sorologias maternas alteradas | F37: 3 | I37: =IF(B37="","",IF(F37<>"",F37,IF(AND(G37<>"",H37<>""),IF(H37=0,"",G37/H37),""))) -> 3 | J37: =IFERROR(VLOOKUP(B37,Referência!$A$5:$I$16,9,FALSE),"") -> quantidade | K37: Um mesmo RN pode apresentar mais de um critério. | L37: Relatório analítico de critérios de risco dos RN | M37: 46276 | N37: Coordenação da Maternidade | O37: Transcrito do documento | P37: =IF(B37="","",IF(OR(A37="",C37="",D37="",E37="",I37="",J37="",L37="",M37="",N37="",O37=""),"INCOMPLETO","COMPLETO")) -> COMPLETO
A38: 46082 | B38: CRITERIOS_RN_RISCO | C38: =IFERROR(VLOOKUP(B38,Referência!$A$5:$I$16,2,FALSE),"") -> Critérios identificados nos RN classificados como de risco | D38: SUS | E38: Desconforto respiratório | F38: 5 | I38: =IF(B38="","",IF(F38<>"",F38,IF(AND(G38<>"",H38<>""),IF(H38=0,"",G38/H38),""))) -> 5 | J38: =IFERROR(VLOOKUP(B38,Referência!$A$5:$I$16,9,FALSE),"") -> quantidade | K38: Um mesmo RN pode apresentar mais de um critério. | L38: Relatório analítico de critérios de risco dos RN | M38: 46276 | N38: Coordenação da Maternidade | O38: Transcrito do documento | P38: =IF(B38="","",IF(OR(A38="",C38="",D38="",E38="",I38="",J38="",L38="",M38="",N38="",O38=""),"INCOMPLETO","COMPLETO")) -> COMPLETO
A39: 46082 | B39: CRITERIOS_RN_RISCO | C39: =IFERROR(VLOOKUP(B39,Referência!$A$5:$I$16,2,FALSE),"") -> Critérios identificados nos RN classificados como de risco | D39: SUS | E39: Baixo peso ao nascer, PIG ou GIG | F39: 3 | I39: =IF(B39="","",IF(F39<>"",F39,IF(AND(G39<>"",H39<>""),IF(H39=0,"",G39/H39),""))) -> 3 | J39: =IFERROR(VLOOKUP(B39,Referência!$A$5:$I$16,9,FALSE),"") -> quantidade | K39: Um mesmo RN pode apresentar mais de um critério. | L39: Relatório analítico de critérios de risco dos RN | M39: 46276 | N39: Coordenação da Maternidade | O39: Transcrito do documento | P39: =IF(B39="","",IF(OR(A39="",C39="",D39="",E39="",I39="",J39="",L39="",M39="",N39="",O39=""),"INCOMPLETO","COMPLETO")) -> COMPLETO
A40: 46082 | B40: CRITERIOS_RN_RISCO | C40: =IFERROR(VLOOKUP(B40,Referência!$A$5:$I$16,2,FALSE),"") -> Critérios identificados nos RN classificados como de risco | D40: SUS | E40: Sofrimento fetal agudo | F40: 2 | I40: =IF(B40="","",IF(F40<>"",F40,IF(AND(G40<>"",H40<>""),IF(H40=0,"",G40/H40),""))) -> 2 | J40: =IFERROR(VLOOKUP(B40,Referência!$A$5:$I$16,9,FALSE),"") -> quantidade | K40: Um mesmo RN pode apresentar mais de um critério. | L40: Relatório analítico de critérios de risco dos RN | M40: 46276 | N40: Coordenação da Maternidade | O40: Transcrito do documento | P40: =IF(B40="","",IF(OR(A40="",C40="",D40="",E40="",I40="",J40="",L40="",M40="",N40="",O40=""),"INCOMPLETO","COMPLETO")) -> COMPLETO
A41: 46082 | B41: CRITERIOS_RN_RISCO | C41: =IFERROR(VLOOKUP(B41,Referência!$A$5:$I$16,2,FALSE),"") -> Critérios identificados nos RN classificados como de risco | D41: SUS | E41: Filho de mãe usuária de drogas | F41: 0 | I41: =IF(B41="","",IF(F41<>"",F41,IF(AND(G41<>"",H41<>""),IF(H41=0,"",G41/H41),""))) -> 0 | J41: =IFERROR(VLOOKUP(B41,Referência!$A$5:$I$16,9,FALSE),"") -> quantidade | K41: Um mesmo RN pode apresentar mais de um critério. | L41: Relatório analítico de critérios de risco dos RN | M41: 46276 | N41: Coordenação da Maternidade | O41: Transcrito do documento | P41: =IF(B41="","",IF(OR(A41="",C41="",D41="",E41="",I41="",J41="",L41="",M41="",N41="",O41=""),"INCOMPLETO","COMPLETO")) -> COMPLETO
A42: 46082 | B42: CRITERIOS_RN_RISCO | C42: =IFERROR(VLOOKUP(B42,Referência!$A$5:$I$16,2,FALSE),"") -> Critérios identificados nos RN classificados como de risco | D42: Saúde suplementar | E42: Má formação congênita | F42: 3 | I42: =IF(B42="","",IF(F42<>"",F42,IF(AND(G42<>"",H42<>""),IF(H42=0,"",G42/H42),""))) -> 3 | J42: =IFERROR(VLOOKUP(B42,Referência!$A$5:$I$16,9,FALSE),"") -> quantidade | K42: Um mesmo RN pode apresentar mais de um critério. | L42: Relatório analítico de critérios de risco dos RN | M42: 46276 | N42: Coordenação da Maternidade | O42: Transcrito do documento | P42: =IF(B42="","",IF(OR(A42="",C42="",D42="",E42="",I42="",J42="",L42="",M42="",N42="",O42=""),"INCOMPLETO","COMPLETO")) -> COMPLETO
A43: 46082 | B43: CRITERIOS_RN_RISCO | C43: =IFERROR(VLOOKUP(B43,Referência!$A$5:$I$16,2,FALSE),"") -> Critérios identificados nos RN classificados como de risco | D43: Saúde suplementar | E43: Prematuridade abaixo de 37 semanas de idade gestacional | F43: 10 | I43: =IF(B43="","",IF(F43<>"",F43,IF(AND(G43<>"",H43<>""),IF(H43=0,"",G43/H43),""))) -> 10 | J43: =IFERROR(VLOOKUP(B43,Referência!$A$5:$I$16,9,FALSE),"") -> quantidade | K43: Um mesmo RN pode apresentar mais de um critério. | L43: Relatório analítico de critérios de risco dos RN | M43: 46276 | N43: Coordenação da Maternidade | O43: Transcrito do documento | P43: =IF(B43="","",IF(OR(A43="",C43="",D43="",E43="",I43="",J43="",L43="",M43="",N43="",O43=""),"INCOMPLETO","COMPLETO")) -> COMPLETO
A44: 46082 | B44: CRITERIOS_RN_RISCO | C44: =IFERROR(VLOOKUP(B44,Referência!$A$5:$I$16,2,FALSE),"") -> Critérios identificados nos RN classificados como de risco | D44: Saúde suplementar | E44: Icterícia em nível de exsanguineotransfusão | F44: 1 | I44: =IF(B44="","",IF(F44<>"",F44,IF(AND(G44<>"",H44<>""),IF(H44=0,"",G44/H44),""))) -> 1 | J44: =IFERROR(VLOOKUP(B44,Referência!$A$5:$I$16,9,FALSE),"") -> quantidade | K44: Um mesmo RN pode apresentar mais de um critério. | L44: Relatório analítico de critérios de risco dos RN | M44: 46276 | N44: Coordenação da Maternidade | O44: Transcrito do documento | P44: =IF(B44="","",IF(OR(A44="",C44="",D44="",E44="",I44="",J44="",L44="",M44="",N44="",O44=""),"INCOMPLETO","COMPLETO")) -> COMPLETO
A45: 46082 | B45: CRITERIOS_RN_RISCO | C45: =IFERROR(VLOOKUP(B45,Referência!$A$5:$I$16,2,FALSE),"") -> Critérios identificados nos RN classificados como de risco | D45: Saúde suplementar | E45: Sepse ou sorologias maternas alteradas | F45: 0 | I45: =IF(B45="","",IF(F45<>"",F45,IF(AND(G45<>"",H45<>""),IF(H45=0,"",G45/H45),""))) -> 0 | J45: =IFERROR(VLOOKUP(B45,Referência!$A$5:$I$16,9,FALSE),"") -> quantidade | K45: Um mesmo RN pode apresentar mais de um critério. | L45: Relatório analítico de critérios de risco dos RN | M45: 46276 | N45: Coordenação da Maternidade | O45: Transcrito do documento | P45: =IF(B45="","",IF(OR(A45="",C45="",D45="",E45="",I45="",J45="",L45="",M45="",N45="",O45=""),"INCOMPLETO","COMPLETO")) -> COMPLETO
... A129: 46235 | B129: CRITERIOS_RN_RISCO | C129: =IFERROR(VLOOKUP(B129,Referência!$A$5:$I$16,2,FALSE),"") -> Critérios identificados nos RN classificados como de risco | D129: Saúde suplementar | E129: Filho de mãe usuária de drogas | F129: 1 | I129: =IF(B129="","",IF(F129<>"",F129,IF(AND(G129<>"",H129<>""),IF(H129=0,"",G129/H129),""))) -> 1 | J129: =IFERROR(VLOOKUP(B129,Referência!$A$5:$I$16,9,FALSE),"") -> quantidade | K129: Um mesmo RN pode apresentar mais de um critério. | L129: Relatório analítico de critérios de risco dos RN | M129: 46276 | N129: Coordenação da Maternidade | O129: Transcrito do documento | P129: =IF(B129="","",IF(OR(A129="",C129="",D129="",E129="",I129="",J129="",L129="",M129="",N129="",O129=""),"INCOMPLETO","COMPLETO")) -> COMPLETO
A130: 46113 | B130: 2103 | C130: =IFERROR(VLOOKUP(B130,Referência!$A$5:$I$16,2,FALSE),"") -> Proporção de recém-nascidos de risco encaminhados ao PIPA | D130: SUS | E130: Sem detalhamento | F130: 0.28 | G130: 5 | H130: 18 | I130: =IF(B130="","",IF(F130<>"",F130,IF(AND(G130<>"",H130<>""),IF(H130=0,"",G130/H130),""))) -> 0.28 | J130: =IFERROR(VLOOKUP(B130,Referência!$A$5:$I$16,9,FALSE),"") -> percentual | K130: Prematuridade e UTI neonatal; VDRL positivo; asfixia perinatal; baixo peso ao nascer. | L130: Relatório cód. 2103 | M130: 46276 | N130: Coordenação da Maternidade | O130: Transcrito do documento | P130: =IF(B130="","",IF(OR(A130="",C130="",D130="",E130="",I130="",J130="",L130="",M130="",N130="",O130=""),"INCOMPLETO","COMPLETO")) -> COMPLETO
A131: 46113 | B131: 2103 | C131: =IFERROR(VLOOKUP(B131,Referência!$A$5:$I$16,2,FALSE),"") -> Proporção de recém-nascidos de risco encaminhados ao PIPA | D131: Saúde suplementar | E131: Sem detalhamento | F131: 0.27 | G131: 3 | H131: 11 | I131: =IF(B131="","",IF(F131<>"",F131,IF(AND(G131<>"",H131<>""),IF(H131=0,"",G131/H131),""))) -> 0.27 | J131: =IFERROR(VLOOKUP(B131,Referência!$A$5:$I$16,9,FALSE),"") -> percentual | K131: Prematuridade e UTI neonatal. | L131: Relatório cód. 2103 | M131: 46276 | N131: Coordenação da Maternidade | O131: Transcrito do documento | P131: =IF(B131="","",IF(OR(A131="",C131="",D131="",E131="",I131="",J131="",L131="",M131="",N131="",O131=""),"INCOMPLETO","COMPLETO")) -> COMPLETO
A132: 46143 | B132: 2103 | C132: =IFERROR(VLOOKUP(B132,Referência!$A$5:$I$16,2,FALSE),"") -> Proporção de recém-nascidos de risco encaminhados ao PIPA | D132: SUS | E132: Sem detalhamento | F132: 0.28 | G132: 5 | H132: 18 | I132: =IF(B132="","",IF(F132<>"",F132,IF(AND(G132<>"",H132<>""),IF(H132=0,"",G132/H132),""))) -> 0.28 | J132: =IFERROR(VLOOKUP(B132,Referência!$A$5:$I$16,9,FALSE),"") -> percentual | K132: Uso materno de drogas ilícitas; RN PIG; VDRL positivo; desconforto respiratório; prematuridade e UTI neonatal; asfixia perinatal. | L132: Relatório cód. 2103 | M132: 46276 | N132: Coordenação da Maternidade | O132: Transcrito do documento | P132: =IF(B132="","",IF(OR(A132="",C132="",D132="",E132="",I132="",J132="",L132="",M132="",N132="",O132=""),"INCOMPLETO","COMPLETO")) -> COMPLETO
A133: 46143 | B133: 2103 | C133: =IFERROR(VLOOKUP(B133,Referência!$A$5:$I$16,2,FALSE),"") -> Proporção de recém-nascidos de risco encaminhados ao PIPA | D133: Saúde suplementar | E133: Sem detalhamento | F133: 0.43 | G133: 7 | H133: 16 | I133: =IF(B133="","",IF(F133<>"",F133,IF(AND(G133<>"",H133<>""),IF(H133=0,"",G133/H133),""))) -> 0.43 | J133: =IFERROR(VLOOKUP(B133,Referência!$A$5:$I$16,9,FALSE),"") -> percentual | K133: Prematuridade e UTI neonatal; RN PIG; VDRL positivo. | L133: Relatório cód. 2103 | M133: 46276 | N133: Coordenação da Maternidade | O133: Transcrito do documento | P133: =IF(B133="","",IF(OR(A133="",C133="",D133="",E133="",I133="",J133="",L133="",M133="",N133="",O133=""),"INCOMPLETO","COMPLETO")) -> COMPLETO
A134: 46174 | B134: 2103 | C134: =IFERROR(VLOOKUP(B134,Referência!$A$5:$I$16,2,FALSE),"") -> Proporção de recém-nascidos de risco encaminhados ao PIPA | D134: SUS | E134: Sem detalhamento | F134: 0.23 | G134: 4 | H134: 17 | I134: =IF(B134="","",IF(F134<>"",F134,IF(AND(G134<>"",H134<>""),IF(H134=0,"",G134/H134),""))) -> 0.23 | J134: =IFERROR(VLOOKUP(B134,Referência!$A$5:$I$16,9,FALSE),"") -> percentual | K134: Prematuridade; baixo peso; doença da membrana hialina; alterações neurológicas; suspeita de trissomia 21; RN GIG; toxoplasmose materna. | L134: Relatório cód. 2103 | M134: 46276 | N134: Coordenação da Maternidade | O134: Transcrito do documento | P134: =IF(B134="","",IF(OR(A134="",C134="",D134="",E134="",I134="",J134="",L134="",M134="",N134="",O134=""),"INCOMPLETO","COMPLETO")) -> COMPLETO
A135: 46174 | B135: 2103 | C135: =IFERROR(VLOOKUP(B135,Referência!$A$5:$I$16,2,FALSE),"") -> Proporção de recém-nascidos de risco encaminhados ao PIPA | D135: Saúde suplementar | E135: Sem detalhamento | F135: 0.3 | G135: 3 | H135: 10 | I135: =IF(B135="","",IF(F135<>"",F135,IF(AND(G135<>"",H135<>""),IF(H135=0,"",G135/H135),""))) -> 0.3 | J135: =IFERROR(VLOOKUP(B135,Referência!$A$5:$I$16,9,FALSE),"") -> percentual | K135: RN GIG; baixo peso e prematuridade; taquipneia transitória; crise convulsiva. | L135: Relatório cód. 2103 | M135: 46276 | N135: Coordenação da Maternidade | O135: Transcrito do documento | P135: =IF(B135="","",IF(OR(A135="",C135="",D135="",E135="",I135="",J135="",L135="",M135="",N135="",O135=""),"INCOMPLETO","COMPLETO")) -> COMPLETO
A136: 46204 | B136: 2103 | C136: =IFERROR(VLOOKUP(B136,Referência!$A$5:$I$16,2,FALSE),"") -> Proporção de recém-nascidos de risco encaminhados ao PIPA | D136: SUS | E136: Sem detalhamento | F136: 0.215 | G136: 3 | H136: 14 | I136: =IF(B136="","",IF(F136<>"",F136,IF(AND(G136<>"",H136<>""),IF(H136=0,"",G136/H136),""))) -> 0.215 | J136: =IFERROR(VLOOKUP(B136,Referência!$A$5:$I$16,9,FALSE),"") -> percentual | K136: Prematuridade; sofrimento fetal agudo; desconforto respiratório. | L136: Relatório cód. 2103 | M136: 46276 | N136: Coordenação da Maternidade | O136: Transcrito do documento | P136: =IF(B136="","",IF(OR(A136="",C136="",D136="",E136="",I136="",J136="",L136="",M136="",N136="",O136=""),"INCOMPLETO","COMPLETO")) -> COMPLETO
A137: 46204 | B137: 2103 | C137: =IFERROR(VLOOKUP(B137,Referência!$A$5:$I$16,2,FALSE),"") -> Proporção de recém-nascidos de risco encaminhados ao PIPA | D137: Saúde suplementar | E137: Sem detalhamento | F137: 0.2 | G137: 2 | H137: 10 | I137: =IF(B137="","",IF(F137<>"",F137,IF(AND(G137<>"",H137<>""),IF(H137=0,"",G137/H137),""))) -> 0.2 | J137: =IFERROR(VLOOKUP(B137,Referência!$A$5:$I$16,9,FALSE),"") -> percentual | K137: Prematuridade; taquipneia transitória. | L137: Relatório cód. 2103 | M137: 46276 | N137: Coordenação da Maternidade | O137: Transcrito do documento | P137: =IF(B137="","",IF(OR(A137="",C137="",D137="",E137="",I137="",J137="",L137="",M137="",N137="",O137=""),"INCOMPLETO","COMPLETO")) -> COMPLETO
A138: 46235 | B138: 2103 | C138: =IFERROR(VLOOKUP(B138,Referência!$A$5:$I$16,2,FALSE),"") -> Proporção de recém-nascidos de risco encaminhados ao PIPA | D138: SUS | E138: Sem detalhamento | F138: 0.4 | G138: 8 | H138: 20 | I138: =IF(B138="","",IF(F138<>"",F138,IF(AND(G138<>"",H138<>""),IF(H138=0,"",G138/H138),""))) -> 0.4 | J138: =IFERROR(VLOOKUP(B138,Referência!$A$5:$I$16,9,FALSE),"") -> percentual | K138: Baixo peso ao nascer; desconforto respiratório agudo. | L138: Relatório cód. 2103 | M138: 46276 | N138: Coordenação da Maternidade | O138: Transcrito do documento | P138: =IF(B138="","",IF(OR(A138="",C138="",D138="",E138="",I138="",J138="",L138="",M138="",N138="",O138=""),"INCOMPLETO","COMPLETO")) -> COMPLETO
A139: 46235 | B139: 2103 | C139: =IFERROR(VLOOKUP(B139,Referência!$A$5:$I$16,2,FALSE),"") -> Proporção de recém-nascidos de risco encaminhados ao PIPA | D139: Saúde suplementar | E139: Sem detalhamento | F139: 0.22 | G139: 2 | H139: 9 | I139: =IF(B139="","",IF(F139<>"",F139,IF(AND(G139<>"",H139<>""),IF(H139=0,"",G139/H139),""))) -> 0.22 | J139: =IFERROR(VLOOKUP(B139,Referência!$A$5:$I$16,9,FALSE),"") -> percentual | K139: Desconforto respiratório; exames maternos alterados. | L139: Relatório cód. 2103 | M139: 46276 | N139: Coordenação da Maternidade | O139: Transcrito do documento | P139: =IF(B139="","",IF(OR(A139="",C139="",D139="",E139="",I139="",J139="",L139="",M139="",N139="",O139=""),"INCOMPLETO","COMPLETO")) -> COMPLETO
A140: 46023 | B140: 2015 | C140: =IFERROR(VLOOKUP(B140,Referência!$A$5:$I$16,2,FALSE),"") -> Taxa de aplicação do instrumento ACCR | D140: SUS | E140: Sem detalhamento | F140: 0.918 | G140: 828 | H140: 902 | I140: =IF(B140="","",IF(F140<>"",F140,IF(AND(G140<>"",H140<>""),IF(H140=0,"",G140/H140),""))) -> 0.918 | J140: =IFERROR(VLOOKUP(B140,Referência!$A$5:$I$16,9,FALSE),"") -> percentual | L140: Relatório cód. 2015 | M140: 46276 | N140: Coordenação da Maternidade | O140: Transcrito do documento | P140: =IF(B140="","",IF(OR(A140="",C140="",D140="",E140="",I140="",J140="",L140="",M140="",N140="",O140=""),"INCOMPLETO","COMPLETO")) -> COMPLETO
...

Sheet Referência
A2: Referência
A4: codigo_indicador | B4: nome_indicador | C4: relatorio_fonte | D4: definicao | E4: metodo_calculo | F4: frequencia | G4: area_referencia | H4: parametro | I4: unidade_medida
A5: 2017 | B5: Percentual de recém-nascidos com amamentação na primeira hora de vida | C5: Relatório cód. 2017 | D5: Proporção de RN amamentados na primeira hora em relação aos nascidos vivos hospitalares. | E5: RN amamentados na 1ª hora / nascidos vivos hospitalares × 100 | F5: Semestral | G5: Residentes de Divinópolis | H5: Acima de 70% | I5: percentual
A6: 2097 | B6: Tempo médio de internação do RN de risco | C6: Relatório cód. 2097 | D6: Tempo médio de internação hospitalar dos RN classificados como de risco. | E6: Soma dos dias de internação / RN de risco internados | F6: Semestral | G6: Residentes de Divinópolis | H6: Não se aplica | I6: dias
A7: CRITERIOS_RN_RISCO | B7: Critérios identificados nos RN classificados como de risco | C7: Relatório analítico | D7: Contagem dos critérios registrados para RN de risco. | E7: Contagem por critério; um RN pode ter mais de um critério | F7: Mensal no documento | G7: Residentes de Divinópolis | H7: Não se aplica | I7: quantidade
A8: 2103 | B8: Proporção de recém-nascidos de risco encaminhados ao PIPA | C8: Relatório cód. 2103 | D8: Proporção de RN de risco encaminhados ao PIPA. | E8: RN encaminhados / RN de risco identificados × 100 | F8: Semestral | G8: Residentes de Divinópolis | H8: Acima de 95% | I8: percentual
A9: 2015 | B9: Taxa de aplicação do instrumento ACCR | C9: Relatório cód. 2015 | D9: Proporção de gestantes admitidas com aplicação registrada do ACCR. | E9: Gestantes com ACCR / gestantes admitidas × 100 | F9: Semestral | G9: Residentes de Divinópolis | H9: Acima de 95% | I9: percentual
A10: 2014 | B10: Taxa de aplicação da classificação de Robson | C10: Relatório cód. 2014 | D10: Proporção de partos classificados segundo Robson. | E10: Partos classificados / total de partos × 100 | F10: Semestral | G10: Residentes de Divinópolis | H10: Acima de 95% | I10: percentual
A11: CRI_MENOR_5 | B11: Crianças menores de 5 anos internadas | C11: Relatório Soul por faixa etária | D11: Quantidade mensal de crianças menores de 5 anos internadas. | E11: Contagem mensal | F11: Semestral | G11: Residentes de Divinópolis | H11: Não se aplica | I11: quantidade
A12: CRI_6_A_9 | B12: Crianças de 6 a 9 anos internadas | C12: Relatório Soul por faixa etária | D12: Quantidade mensal de crianças de 6 a 9 anos internadas. | E12: Contagem mensal | F12: Não informada | G12: Residentes de Divinópolis | H12: Não se aplica | I12: quantidade
A13: PARTOS | B13: Quantidade de partos por tipo | C13: Planilha de partos do BO | D13: Quantidade de partos normais e cesáreos por atendimento e risco. | E13: Contagem por tipo; percentual = tipo / total × 100 | F13: Semestral | G13: Residentes de Divinópolis | H13: 10% a 15% de partos cesáreos | I13: quantidade
A14: PORTA_MEDICO | B14: Tempo médio de espera porta-médico hospitalar | C14: Relatório 2024 | D14: Tempo médio entre chegada e primeiro atendimento médico. | E14: Soma dos tempos / total de atendimentos | F14: Semestral | G14: Residentes de Divinópolis | H14: Não se aplica | I14: minutos
A15: PA_PREPARTO | B15: Tempo médio de espera do pronto atendimento ao pré-parto | C15: Relatório 2023 | D15: Tempo médio entre chegada e recebimento no pré-parto. | E15: Soma dos tempos / total de atendimentos | F15: Semestral | G15: Residentes de Divinópolis | H15: Não se aplica | I15: minutos
A16: ICSAP | B16: Percentual de internações por condições sensíveis à atenção primária | C16: Relatório específico do DRG | D16: Proporção de internações por causas sensíveis à APS. | E16: Internações por condições sensíveis / total de internações × 100 | F16: Semestral | G16: Residentes de Divinópolis | H16: Abaixo de 20% | I16: percentual

Sheet Como_preencher
A2: Como usar a planilha
A5: Regras de preenchimento
A6: 1 | B6: Uma linha representa um resultado de um indicador, período, atendimento e detalhamento.
A7: 2 | B7: Ao selecionar codigo_indicador, nome_indicador e unidade_medida são preenchidos automaticamente.
A8: 3 | B8: Se o documento trouxer o resultado pronto, preencha resultado_informado.
A9: 4 | B9: Se houver somente numerador e denominador, deixe resultado_informado vazio; o resultado será calculado.
A10: 6 | B10: Amarelo indica entrada manual; verde indica campo automático.

Sheet Listas_de_opcoes
A1: tipo_atendimento | B1: unidade_medida | C1: situacao_do_dado | D1: detalhamento_comum
A2: SUS | B2: percentual | C2: Em elaboração | D2: Sem detalhamento
A3: Saúde suplementar | B3: dias | C3: Revisado | D3: Todas as classificações
A4: Geral | B4: minutos | C4: Validado | D4: Amarelas e laranjas
A5: Não se aplica | B5: quantidade | C5: Retificado | D5: Azul e verde
D6: Residentes de Divinópolis
